<?xml version="1.0"?>
<robot xmlns:xacro="http://wiki.ros.org/xacro">
  <xacro:macro name="kuka_kr16_r2010_2_robot" params="prefix package_name">
    <!-- links - main serial chain -->
    <link name="${prefix}base_link">
      <collision>
        <geometry>
          <mesh filename="package://${package_name}/meshes/kr16_r2010_2/collision/base_link.stl"/>
        </geometry>
        <origin rpy="-0.0 0.0 -0.0" xyz="0.0 0.0 0.0"/>
      </collision>
      <inertial>
        <mass value="6.5E1"/>
        <origin rpy="0.0 0.0 0.0" xyz="0.0 0.0 0.15"/>
        <inertia ixx="1.0" ixy="0.0" ixz="0.0" iyy="1.0" iyz="0.0" izz="1.5"/>
      </inertial>
      <visual>
        <geometry>
          <mesh filename="package://${package_name}/meshes/kr16_r2010_2/visual/base_link.stl"/>
        </geometry>
        <origin rpy="-0.0 0.0 -0.0" xyz="0.0 0.0 0.0"/>
        <material name="KukaOrange">
          <color rgba="1.0 0.4 0.0 1.0"/>
        </material>
      </visual>
    </link>
    <link name="${prefix}link_1">
      <collision>
        <geometry>
          <mesh filename="package://${package_name}/meshes/kr16_r2010_2/collision/link_1.stl"/>
        </geometry>
        <origin rpy="-0.0 0.0 -0.0" xyz="0.0 0.0 0.0"/>
      </collision>
      <inertial>
        <mass value="8.4207E1"/>
        <origin rpy="0.0 0.0 0.0" xyz="0.05 0.005 -0.26"/>
        <inertia ixx="2.0" ixy="0.0" ixz="0.0" iyy="2.0" iyz="0.0" izz="4.0"/>
      </inertial>
      <visual>
        <geometry>
          <mesh filename="package://${package_name}/meshes/kr16_r2010_2/visual/link_1.stl"/>
        </geometry>
        <origin rpy="-0.0 0.0 -0.0" xyz="0.0 0.0 0.0"/>
        <material name="KukaOrange">
          <color rgba="1.0 0.4 0.0 1.0"/>
        </material>
      </visual>
    </link>
    <link name="${prefix}link_2">
      <collision>
        <geometry>
          <mesh filename="package://${package_name}/meshes/kr16_r2010_2/collision/link_2.stl"/>
        </geometry>
        <origin rpy="-0.0 0.0 -0.0" xyz="0.0 0.0 0.0"/>
      </collision>
      <inertial>
        <mass value="5.5E1"/>
        <origin rpy="0.0 0.0 0.0" xyz="0.49 0.0 0.0"/>
        <inertia ixx="0.5" ixy="0.0" ixz="0.0" iyy="4.4" iyz="0.0" izz="4.4"/>
      </inertial>
      <visual>
        <geometry>
          <mesh filename="package://${package_name}/meshes/kr16_r2010_2/visual/link_2.stl"/>
        </geometry>
        <origin rpy="-0.0 0.0 -0.0" xyz="0.0 0.0 0.0"/>
        <material name="KukaOrange">
          <color rgba="1.0 0.4 0.0 1.0"/>
        </material>
      </visual>
    </link>
    <link name="${prefix}link_3">
      <collision>
        <geometry>
          <mesh filename="package://${package_name}/meshes/kr16_r2010_2/collision/link_3.stl"/>
        </geometry>
        <origin rpy="-0.0 0.0 -0.0" xyz="0.0 0.0 0.0"/>
      </collision>
      <inertial>
        <mass value="1.5E1"/>
        <origin rpy="0.0 0.0 0.0" xyz="0.075 0.0 0.0"/>
        <inertia ixx="0.3" ixy="0.0" ixz="0.0" iyy="0.5" iyz="0.0" izz="0.5"/>
      </inertial>
      <visual>
        <geometry>
          <mesh filename="package://${package_name}/meshes/kr16_r2010_2/visual/link_3.stl"/>
        </geometry>
        <origin rpy="-0.0 0.0 -0.0" xyz="0.0 0.0 0.0"/>
        <material name="KukaOrange">
          <color rgba="1.0 0.4 0.0 1.0"/>
        </material>
      </visual>
    </link>
    <link name="${prefix}link_4">
      <collision>
        <geometry>
          <mesh filename="package://${package_name}/meshes/kr16_r2010_2/collision/link_4.stl"/>
        </geometry>
        <origin rpy="-0.0 0.0 -0.0" xyz="0.0 0.0 0.0"/>
      </collision>
      <inertial>
        <mass value="1.2E1"/>
        <origin rpy="0.0 0.0 0.0" xyz="0.0 0.0 -0.43"/>
        <inertia ixx="0.74" ixy="0.0" ixz="0.0" iyy="0.74" iyz="0.0" izz="0.05"/>
      </inertial>
      <visual>
        <geometry>
          <mesh filename="package://${package_name}/meshes/kr16_r2010_2/visual/link_4.stl"/>
        </geometry>
        <origin rpy="-0.0 0.0 -0.0" xyz="0.0 0.0 0.0"/>
        <material name="KukaOrange">
          <color rgba="1.0 0.4 0.0 1.0"/>
        </material>
      </visual>
    </link>
    <link name="${prefix}link_5">
      <collision>
        <geometry>
          <mesh filename="package://${package_name}/meshes/kr16_r2010_2/collision/link_5.stl"/>
        </geometry>
        <origin rpy="-0.0 0.0 -0.0" xyz="0.0 0.0 0.0"/>
      </collision>
      <inertial>
        <mass value="5.0"/>
        <origin rpy="0.0 0.0 0.0" xyz="0.0 0.0 0.0"/>
        <inertia ixx="0.03" ixy="0.0" ixz="0.0" iyy="0.03" iyz="0.0" izz="0.03"/>
      </inertial>
      <visual>
        <geometry>
          <mesh filename="package://${package_name}/meshes/kr16_r2010_2/visual/link_5.stl"/>
        </geometry>
        <origin rpy="-0.0 0.0 -0.0" xyz="0.0 0.0 0.0"/>
        <material name="KukaOrange">
          <color rgba="1.0 0.4 0.0 1.0"/>
        </material>
      </visual>
    </link>
    <link name="${prefix}link_6">
      <collision>
        <geometry>
          <mesh filename="package://${package_name}/meshes/kr16_r2010_2/collision/link_6.stl"/>
        </geometry>
        <origin rpy="-0.0 0.0 -0.0" xyz="0.0 0.0 0.0"/>
      </collision>
      <inertial>
        <mass value="4.0"/>
        <origin rpy="0.0 0.0 0.0" xyz="0.0 0.0 -0.077"/>
        <inertia ixx="0.008" ixy="0.0" ixz="0.0" iyy="0.008" iyz="0.0" izz="0.005"/>
      </inertial>
      <visual>
        <geometry>
          <mesh filename="package://${package_name}/meshes/kr16_r2010_2/visual/link_6.stl"/>
        </geometry>
        <origin rpy="-0.0 0.0 -0.0" xyz="0.0 0.0 0.0"/>
        <material name="KukaOrange">
          <color rgba="1.0 0.4 0.0 1.0"/>
        </material>
      </visual>
    </link>
    <joint name="${prefix}joint_1" type="revolute">
      <axis xyz="0.0 0.0 1.0"/>
      <child link="${prefix}link_1"/>
      <limit effort="1905.3" lower="-3.2288591162E0" upper="3.2288591161895095E0" velocity="${radians(200)}"/>
      <origin rpy="${-pi} 0.0 -0.0" xyz="0.0 0.0 0.0"/>
      <parent link="${prefix}base_link"/>
      <dynamics damping="25.0" friction="0.0"/>
    </joint>
    <joint name="${prefix}joint_2" type="revolute">
      <axis xyz="0.0 0.0 1.0"/>
      <child link="${prefix}link_2"/>
      <limit effort="1633.6259859" lower="-3.2288591161895095E0" upper="1.1344640137963142E0" velocity="${radians(175)}"/>
      <origin rpy="${pi/2.0} 0.0 -0.0" xyz="0.16 0.0 -0.52"/>
      <parent link="${prefix}link_1"/>
      <dynamics damping="25.0" friction="0.0"/>
    </joint>
    <joint name="${prefix}joint_3" type="revolute">
      <axis xyz="0.0 0.0 1.0"/>
      <child link="${prefix}link_3"/>
      <limit effort="850.58019869" lower="-2.4085543677521746E0" upper="3.0543261909900767E0" velocity="${radians(190)}"/>
      <origin rpy="0.0 0.0 ${-pi/2.0}" xyz="0.98 0.0 0.0"/>
      <parent link="${prefix}link_2"/>
      <dynamics damping="5.0" friction="0.0"/>
    </joint>
    <joint name="${prefix}joint_4" type="revolute">
      <axis xyz="0.0 0.0 1.0"/>
      <child link="${prefix}link_4"/>
      <limit effort="266.21043332" lower="-6.1086523819801535E0" upper="6.1086523819801535E0" velocity="${radians(430)}"/>
      <origin rpy="${pi/2.0} 0.0 -0.0" xyz="0.15 0.0 0.0"/>
      <parent link="${prefix}link_3"/>
      <dynamics damping="1.0" friction="0.0"/>
    </joint>
    <joint name="${prefix}joint_5" type="revolute">
      <axis xyz="0.0 0.0 1.0"/>
      <child link="${prefix}link_5"/>
      <limit effort="255.43776663" lower="-2.268928027593E0" upper="2.2689280275926285E0" velocity="${radians(430)}"/>
      <origin rpy="${-pi/2.0} 0.0 -0.0" xyz="0.0 0.0 -0.86"/>
      <parent link="${prefix}link_4"/>
      <dynamics damping="1.0" friction="0.0"/>
    </joint>
    <joint name="${prefix}joint_6" type="revolute">
      <axis xyz="0.0 0.0 1.0"/>
      <child link="${prefix}link_6"/>
      <limit effort="111.65796" lower="-6.1086523819801535E0" upper="6.1086523819801535E0" velocity="${radians(630)}"/>
      <origin rpy="${pi/2.0} 0.0 -0.0" xyz="0.0 0.0 0.0"/>
      <parent link="${prefix}link_5"/>
      <dynamics damping="0.5" friction="0.0"/>
    </joint>
    <!-- ROS-Industrial 'base' frame - equivalent of 'KUKA ROBROOT'-->
    <link name="${prefix}base"/>
    <joint name="${prefix}base_link-base" type="fixed">
      <origin xyz="0 0 0" rpy="0 0 0"/>
      <parent link="${prefix}base_link"/>
      <child link="${prefix}base"/>
    </joint>
    <!-- ROS-Industrial 'flange' frame - attachment point for EEF models -->
    <link name="${prefix}flange"/>
    <joint name="${prefix}link6-flange" type="fixed">
      <child link="${prefix}flange"/>
      <origin rpy="0 ${pi/2} -0.0" xyz="0.0 0.0 -0.153"/>
      <parent link="${prefix}link_6"/>
    </joint>
    <!-- ROS-Industrial 'tool0' frame - all-zeros tool frame -->
    <link name="${prefix}tool0"/>
    <joint name="${prefix}link6-tool0" type="fixed">
      <child link="${prefix}tool0"/>
      <origin rpy="0 ${pi} -0.0" xyz="0.0 0.0 -0.153"/>
      <parent link="${prefix}link_6"/>
    </joint>
  </xacro:macro>
</robot>
